<robot name="vr_h3_1" version="1.0">
  <mujoco>
    <compiler meshdir="../../meshes/vr_h3_1" discardvisual="false" fusestatic="false" />
  </mujoco>
  <link name="pelvis">
    <inertial>
      <origin xyz="0.00039 0.00001 0.02925" rpy="0 0 0" />
      <mass value="3.6443999" />
      <inertia ixx="0.0121675" ixy="0" ixz="0.0000335" iyy="0.0084252" iyz="0" izz="0.0094917" />
    </inertial>
    <collision name="Geom_1">
      <origin xyz="0 0 0.027502" rpy="0 0 0" />
      <geometry>
        <box size="0.115 0.1 0.125" />
      </geometry>
    </collision>
  </link>
  <joint name="left_hip_pitch_joint" type="revolute">
    <origin xyz="0 0.13345 0" rpy="0 0 0" />
    <axis xyz="0 1 0" />
    <parent link="pelvis" />
    <child link="left_hip_pitch_link" />
    <limit effort="369" lower="-1.5710001" upper="0.436" velocity="3.141" />
  </joint>
  <link name="left_hip_pitch_link">
    <inertial>
      <origin xyz="-0.00237 -0.00815 0.00015" rpy="0 0 0" />
      <mass value="3.4639399" />
      <inertia ixx="0.0050216" ixy="-0.0000731" ixz="-0.0000772" iyy="0.006814" iyz="0" izz="0.0056809" />
    </inertial>
  </link>
  <joint name="left_hip_roll_joint" type="revolute">
    <origin xyz="0 0 0" rpy="0 0 0" />
    <axis xyz="1 0 0" />
    <parent link="left_hip_pitch_link" />
    <child link="left_hip_roll_link" />
    <limit effort="369" lower="-0.175" upper="1.0470001" velocity="3.141" />
  </joint>
  <link name="left_hip_roll_link">
    <inertial>
      <origin xyz="-0.05315 0.00019 -0.05534" rpy="0 0 0" />
      <mass value="5.4108" />
      <inertia ixx="0.0303418" ixy="0.0000224" ixz="-0.015695" iyy="0.0468964" iyz="0.0000152" izz="0.0245825" />
    </inertial>
    <collision name="Geom_4">
      <origin xyz="0 0 -0.074544" rpy="1.5707965 0 1.5707964" />
      <geometry>
        <box size="0.131402 0.188912 0.179402" />
      </geometry>
    </collision>
    <collision name="Geom_5">
      <origin xyz="-0.119701 0 -0.000506" rpy="1.5707965 0 1.5707964" />
      <geometry>
        <box size="0.131402 0.131402 0.06" />
      </geometry>
    </collision>
  </link>
  <joint name="left_hip_yaw_joint" type="revolute">
    <origin xyz="0 0 -0.163" rpy="0 0 0" />
    <axis xyz="0 0 1" />
    <parent link="left_hip_roll_link" />
    <child link="left_hip_yaw_link" />
    <limit effort="191" lower="-0.785" upper="0.785" velocity="3.141" />
  </joint>
  <link name="left_hip_yaw_link">
    <inertial>
      <origin xyz="0.00114 0.00594 -0.16274" rpy="0 0 0" />
      <mass value="4.2223802" />
      <inertia ixx="0.0187522" ixy="-0.0000267" ixz="0.0002027" iyy="0.0198656" iyz="-0.0006361" izz="0.0065082" />
    </inertial>
    <collision name="Geom_7">
      <origin xyz="0 0 -0.04" rpy="0 0 -3.1415925" />
      <geometry>
        <box size="0.128214 0.128214 0.05693" />
      </geometry>
    </collision>
  </link>
  <joint name="left_knee_pitch_joint" type="revolute">
    <origin xyz="0 0 -0.19" rpy="0 0 0" />
    <axis xyz="0 1 0" />
    <parent link="left_hip_yaw_link" />
    <child link="left_knee_pitch_link" />
    <limit effort="369" lower="-0.175" upper="2.094" velocity="3.141" />
  </joint>
  <link name="left_knee_pitch_link">
    <inertial>
      <origin xyz="-0.0093 0.00077 -0.17313" rpy="0 0 0" />
      <mass value="4.5156202" />
      <inertia ixx="0.0545066" ixy="0.0000507" ixz="-0.0004952" iyy="0.0536595" iyz="0.0002263" izz="0.0081416" />
    </inertial>
    <collision name="Geom_9">
      <origin xyz="-0.008043 0 -0.031032" rpy="-0.9827936 -1.5707961 -0.5880025" />
      <geometry>
        <box size="0.182882 0.110882 0.114882" />
      </geometry>
    </collision>
    <collision name="Geom_10">
      <origin xyz="-0.018343 0 -0.191913" rpy="-0.9827936 -1.5707961 -0.5880025" />
      <geometry>
        <box size="0.138882 0.138882 0.118882" />
      </geometry>
    </collision>
    <collision name="Geom_11">
      <origin xyz="-0.0020331 0 -0.320795" rpy="-0.9827936 -1.5707961 -0.5880025" />
      <geometry>
        <box size="0.118882 0.100882 0.104882" />
      </geometry>
    </collision>
  </link>
  <joint name="left_ankle_pitch_joint" type="revolute">
    <origin xyz="0 0 -0.434" rpy="0 0 0" />
    <axis xyz="0 1 0" />
    <parent link="left_knee_pitch_link" />
    <child link="left_ankle_pitch_link" />
    <limit effort="140" lower="-0.873" upper="0.524" velocity="3.141" />
  </joint>
  <link name="left_ankle_pitch_link">
    <inertial>
      <origin xyz="-0.00032 0 -0.00762" rpy="0 0 0" />
      <mass value="0.08624" />
      <inertia ixx="0.0000164" ixy="0" ixz="0" iyy="0.0000179" iyz="0" izz="0.0000133" />
    </inertial>
  </link>
  <joint name="left_foot_0_joint" type="fixed">
    <origin xyz="0.195892 -0.005 -0.035" rpy="-2.55359 -1.5707961 -0.5880025" />
    <parent link="left_ankle_roll_link" />
    <child link="left_foot_0" />
  </joint>
  <link name="left_foot_0">
    <collision>
      <origin xyz="0 0 0" rpy="0 0 0" />
      <geometry>
        <sphere radius="0.005" />
      </geometry>
    </collision>
  </link>
  <joint name="left_foot_1_joint" type="fixed">
    <origin xyz="0.11662 -0.05 -0.035" rpy="-2.55359 -1.5707961 -0.5880025" />
    <parent link="left_ankle_roll_link" />
    <child link="left_foot_1" />
  </joint>
  <link name="left_foot_1">
    <collision>
      <origin xyz="0 0 0" rpy="0 0 0" />
      <geometry>
        <sphere radius="0.005" />
      </geometry>
    </collision>
  </link>
  <joint name="left_foot_2_joint" type="fixed">
    <origin xyz="0.11662 0.045 -0.035" rpy="-2.55359 -1.5707961 -0.5880025" />
    <parent link="left_ankle_roll_link" />
    <child link="left_foot_2" />
  </joint>
  <link name="left_foot_2">
    <collision>
      <origin xyz="0 0 0" rpy="0 0 0" />
      <geometry>
        <sphere radius="0.005" />
      </geometry>
    </collision>
  </link>
  <joint name="left_foot_3_joint" type="fixed">
    <origin xyz="-0.055879 -0.023 -0.035" rpy="-2.55359 -1.5707961 -0.5880025" />
    <parent link="left_ankle_roll_link" />
    <child link="left_foot_3" />
  </joint>
  <link name="left_foot_3">
    <collision>
      <origin xyz="0 0 0" rpy="0 0 0" />
      <geometry>
        <sphere radius="0.005" />
      </geometry>
    </collision>
  </link>
  <joint name="left_foot_4_joint" type="fixed">
    <origin xyz="-0.055879 0.025 -0.035" rpy="-2.55359 -1.5707961 -0.5880025" />
    <parent link="left_ankle_roll_link" />
    <child link="left_foot_4" />
  </joint>
  <link name="left_foot_4">
    <collision>
      <origin xyz="0 0 0" rpy="0 0 0" />
      <geometry>
        <sphere radius="0.005" />
      </geometry>
    </collision>
  </link>
  <joint name="left_ankle_roll_joint" type="revolute">
    <origin xyz="0 0 -0.014" rpy="0 0 0" />
    <axis xyz="1 0 0" />
    <parent link="left_ankle_pitch_link" />
    <child link="left_ankle_roll_link" />
    <limit effort="140" lower="-0.262" upper="0.262" velocity="3.141" />
  </joint>
  <link name="left_ankle_roll_link">
    <inertial>
      <origin xyz="0.05279 0.00065 -0.017" rpy="0 0 0" />
      <mass value="1.1573499" />
      <inertia ixx="0.0011046" ixy="0.00012" ixz="-0.0001748" iyy="0.0053972" iyz="0" izz="0.0059126" />
    </inertial>
    <collision name="Geom_14">
      <origin xyz="0.130397 0 0.010702" rpy="-2.55359 -1.5707961 -0.5880025" />
      <geometry>
        <box size="0.029938 0.07601 0.078294" />
      </geometry>
    </collision>
    <collision name="Geom_15">
      <origin xyz="-0.051815 0 0.010702" rpy="-2.55359 -1.5707961 -0.5880025" />
      <geometry>
        <box size="0.029938 0.07201 0.018294" />
      </geometry>
    </collision>
    <collision name="Geom_16">
      <origin xyz="0.186905 -0.005512 -0.015237" rpy="-2.55359 -1.5707961 -0.5880025" />
      <geometry>
        <box size="0.021938 0.04401 0.02" />
      </geometry>
    </collision>
    <collision name="Geom_17">
      <origin xyz="0.064757 0 -0.015237" rpy="-2.55359 -1.5707961 -0.5880025" />
      <geometry>
        <box size="0.021938 0.09001 0.224294" />
      </geometry>
    </collision>
    <collision name="Geom_18">
      <origin xyz="-0.055537 0.004563 -0.015237" rpy="-2.55359 -1.5707961 -0.5880025" />
      <geometry>
        <box size="0.021938 0.05601 0.016294" />
      </geometry>
    </collision>
  </link>
  <joint name="right_hip_pitch_joint" type="revolute">
    <origin xyz="0 -0.13345 0" rpy="0 0 0" />
    <axis xyz="0 1 0" />
    <parent link="pelvis" />
    <child link="right_hip_pitch_link" />
    <limit effort="369" lower="-1.5710001" upper="0.436" velocity="3.141" />
  </joint>
  <link name="right_hip_pitch_link">
    <inertial>
      <origin xyz="-0.00237 0.00815 0.00015" rpy="0 0 0" />
      <mass value="3.4639399" />
      <inertia ixx="0.0050216" ixy="0.0000731" ixz="-0.0000772" iyy="0.006814" iyz="0" izz="0.0056809" />
    </inertial>
  </link>
  <joint name="right_hip_roll_joint" type="revolute">
    <origin xyz="0 0 0" rpy="0 0 0" />
    <axis xyz="1 0 0" />
    <parent link="right_hip_pitch_link" />
    <child link="right_hip_roll_link" />
    <limit effort="369" lower="-1.0470001" upper="0.175" velocity="3.141" />
  </joint>
  <link name="right_hip_roll_link">
    <inertial>
      <origin xyz="-0.05315 -0.00019 -0.05534" rpy="0 0 0" />
      <mass value="5.4108" />
      <inertia ixx="0.0303418" ixy="-0.0000224" ixz="-0.015695" iyy="0.0468964" iyz="-0.0000152" izz="0.0245825" />
    </inertial>
    <collision name="Geom_26">
      <origin xyz="0 0 -0.074544" rpy="1.5707965 0 1.5707964" />
      <geometry>
        <box size="0.131402 0.188912 0.179402" />
      </geometry>
    </collision>
    <collision name="Geom_27">
      <origin xyz="-0.119701 0 -0.000506" rpy="1.5707965 0 1.5707964" />
      <geometry>
        <box size="0.131402 0.131402 0.06" />
      </geometry>
    </collision>
  </link>
  <joint name="right_hip_yaw_joint" type="revolute">
    <origin xyz="0 0 -0.163" rpy="0 0 0" />
    <axis xyz="0 0 1" />
    <parent link="right_hip_roll_link" />
    <child link="right_hip_yaw_link" />
    <limit effort="191" lower="-0.785" upper="0.785" velocity="3.141" />
  </joint>
  <link name="right_hip_yaw_link">
    <inertial>
      <origin xyz="0.00114 -0.00594 -0.16274" rpy="0 0 0" />
      <mass value="4.2223802" />
      <inertia ixx="0.0187522" ixy="0.0000267" ixz="0.0002027" iyy="0.0198656" iyz="0.0006361" izz="0.0065082" />
    </inertial>
    <collision name="Geom_29">
      <origin xyz="0 0 -0.04" rpy="0 0 -3.1415925" />
      <geometry>
        <box size="0.128214 0.128214 0.05693" />
      </geometry>
    </collision>
  </link>
  <joint name="right_knee_pitch_joint" type="revolute">
    <origin xyz="0 0 -0.19" rpy="0 0 0" />
    <axis xyz="0 1 0" />
    <parent link="right_hip_yaw_link" />
    <child link="right_knee_pitch_link" />
    <limit effort="369" lower="-0.175" upper="2.094" velocity="3.141" />
  </joint>
  <link name="right_knee_pitch_link">
    <inertial>
      <origin xyz="-0.0093 -0.00077 -0.17313" rpy="0 0 0" />
      <mass value="4.5156202" />
      <inertia ixx="0.0545066" ixy="-0.0000507" ixz="-0.0004952" iyy="0.0536595" iyz="-0.0002263" izz="0.0081416" />
    </inertial>
    <collision name="Geom_31">
      <origin xyz="-0.008043 0 -0.031032" rpy="-0.9827936 -1.5707961 -0.5880025" />
      <geometry>
        <box size="0.182882 0.110882 0.114882" />
      </geometry>
    </collision>
    <collision name="Geom_32">
      <origin xyz="-0.018343 0 -0.191913" rpy="-0.9827936 -1.5707961 -0.5880025" />
      <geometry>
        <box size="0.138882 0.138882 0.118882" />
      </geometry>
    </collision>
    <collision name="Geom_33">
      <origin xyz="-0.0020331 0 -0.320795" rpy="-0.9827936 -1.5707961 -0.5880025" />
      <geometry>
        <box size="0.118882 0.100882 0.104882" />
      </geometry>
    </collision>
  </link>
  <joint name="right_ankle_pitch_joint" type="revolute">
    <origin xyz="0 0 -0.434" rpy="0 0 0" />
    <axis xyz="0 1 0" />
    <parent link="right_knee_pitch_link" />
    <child link="right_ankle_pitch_link" />
    <limit effort="140" lower="-0.873" upper="0.524" velocity="3.141" />
  </joint>
  <link name="right_ankle_pitch_link">
    <inertial>
      <origin xyz="-0.00032 0 -0.00762" rpy="0 0 0" />
      <mass value="0.08624" />
      <inertia ixx="0.0000164" ixy="0" ixz="0" iyy="0.0000179" iyz="0" izz="0.0000133" />
    </inertial>
  </link>
  <joint name="right_foot_0_joint" type="fixed">
    <origin xyz="0.195892 0.005 -0.035" rpy="-2.55359 -1.5707961 -0.5880025" />
    <parent link="right_ankle_roll_link" />
    <child link="right_foot_0" />
  </joint>
  <link name="right_foot_0">
    <collision>
      <origin xyz="0 0 0" rpy="0 0 0" />
      <geometry>
        <sphere radius="0.005" />
      </geometry>
    </collision>
  </link>
  <joint name="right_foot_1_joint" type="fixed">
    <origin xyz="0.11662 0.05 -0.035" rpy="-2.55359 -1.5707961 -0.5880025" />
    <parent link="right_ankle_roll_link" />
    <child link="right_foot_1" />
  </joint>
  <link name="right_foot_1">
    <collision>
      <origin xyz="0 0 0" rpy="0 0 0" />
      <geometry>
        <sphere radius="0.005" />
      </geometry>
    </collision>
  </link>
  <joint name="right_foot_2_joint" type="fixed">
    <origin xyz="0.11662 -0.045 -0.035" rpy="-2.55359 -1.5707961 -0.5880025" />
    <parent link="right_ankle_roll_link" />
    <child link="right_foot_2" />
  </joint>
  <link name="right_foot_2">
    <collision>
      <origin xyz="0 0 0" rpy="0 0 0" />
      <geometry>
        <sphere radius="0.005" />
      </geometry>
    </collision>
  </link>
  <joint name="right_foot_3_joint" type="fixed">
    <origin xyz="-0.055879 0.023 -0.035" rpy="-2.55359 -1.5707961 -0.5880025" />
    <parent link="right_ankle_roll_link" />
    <child link="right_foot_3" />
  </joint>
  <link name="right_foot_3">
    <collision>
      <origin xyz="0 0 0" rpy="0 0 0" />
      <geometry>
        <sphere radius="0.005" />
      </geometry>
    </collision>
  </link>
  <joint name="right_foot_4_joint" type="fixed">
    <origin xyz="-0.055879 -0.025 -0.035" rpy="-2.55359 -1.5707961 -0.5880025" />
    <parent link="right_ankle_roll_link" />
    <child link="right_foot_4" />
  </joint>
  <link name="right_foot_4">
    <collision>
      <origin xyz="0 0 0" rpy="0 0 0" />
      <geometry>
        <sphere radius="0.005" />
      </geometry>
    </collision>
  </link>
  <joint name="right_ankle_roll_joint" type="revolute">
    <origin xyz="0 0 -0.014" rpy="0 0 0" />
    <axis xyz="1 0 0" />
    <parent link="right_ankle_pitch_link" />
    <child link="right_ankle_roll_link" />
    <limit effort="140" lower="-0.262" upper="0.262" velocity="3.141" />
  </joint>
  <link name="right_ankle_roll_link">
    <inertial>
      <origin xyz="0.05279 -0.00065 -0.017" rpy="0 0 0" />
      <mass value="1.1573499" />
      <inertia ixx="0.0011046" ixy="-0.00012" ixz="-0.0001748" iyy="0.0053972" iyz="0" izz="0.0059126" />
    </inertial>
    <collision name="Geom_36">
      <origin xyz="0.130397 0 0.010702" rpy="-2.55359 -1.5707961 -0.5880025" />
      <geometry>
        <box size="0.029938 0.07601 0.078294" />
      </geometry>
    </collision>
    <collision name="Geom_37">
      <origin xyz="-0.051815 0 0.010702" rpy="-2.55359 -1.5707961 -0.5880025" />
      <geometry>
        <box size="0.029938 0.07201 0.018294" />
      </geometry>
    </collision>
    <collision name="Geom_38">
      <origin xyz="0.186905 0.005512 -0.015237" rpy="-2.55359 -1.5707961 -0.5880025" />
      <geometry>
        <box size="0.021938 0.04401 0.02" />
      </geometry>
    </collision>
    <collision name="Geom_39">
      <origin xyz="0.064757 0 -0.015237" rpy="-2.55359 -1.5707961 -0.5880025" />
      <geometry>
        <box size="0.021938 0.09001 0.224294" />
      </geometry>
    </collision>
    <collision name="Geom_40">
      <origin xyz="-0.055537 -0.004563 -0.015237" rpy="-2.55359 -1.5707961 -0.5880025" />
      <geometry>
        <box size="0.021938 0.05601 0.016294" />
      </geometry>
    </collision>
  </link>
  <joint name="waist_yaw_joint" type="revolute">
    <origin xyz="0 0 0.151" rpy="0 0 0" />
    <axis xyz="0 0 1" />
    <parent link="pelvis" />
    <child link="waist_yaw_link" />
    <limit effort="102" lower="-2.618" upper="2.618" velocity="4.18" />
  </joint>
  <link name="waist_yaw_link">
    <inertial>
      <origin xyz="-0.0064 -0.00001 -0.00609" rpy="0 0 0" />
      <mass value="1.97052" />
      <inertia ixx="0.0023615" ixy="0" ixz="-0.0000636" iyy="0.0028637" iyz="0" izz="0.002521" />
    </inertial>
  </link>
  <joint name="waist_roll_joint" type="revolute">
    <origin xyz="0 0 0" rpy="0 0 0" />
    <axis xyz="1 0 0" />
    <parent link="waist_yaw_link" />
    <child link="waist_roll_link" />
    <limit effort="102" lower="-0.262" upper="0.262" velocity="4.18" />
  </joint>
  <link name="waist_roll_link">
    <inertial>
      <origin xyz="-0.03119 0.0007 0.23753" rpy="0 0 0" />
      <mass value="22.2136993" />
      <inertia ixx="0.4604957" ixy="0.0002448" ixz="0.0244272" iyy="0.3930425" iyz="-0.0021933" izz="0.2119838" />
    </inertial>
    <collision name="Geom_48">
      <origin xyz="-0.002 0 0.38" rpy="-3.1415925 -1.5707963 0" />
      <geometry>
        <box size="0.1 0.29 0.2" />
      </geometry>
    </collision>
    <collision name="Geom_49">
      <origin xyz="-0.002 0 0.23" rpy="-3.1415925 -1.5707963 0" />
      <geometry>
        <box size="0.2 0.302 0.248" />
      </geometry>
    </collision>
    <collision name="Geom_50">
      <origin xyz="-0.005 0 0.08" rpy="-3.1415925 -1.5707963 0" />
      <geometry>
        <box size="0.1 0.29 0.24" />
      </geometry>
    </collision>
  </link>
  <joint name="left_shoulder_pitch_joint" type="revolute">
    <origin xyz="0 0.2075 0.36753" rpy="0 0 0" />
    <axis xyz="0 0.9962185 0.0868828" />
    <parent link="waist_roll_link" />
    <child link="left_shoulder_pitch_link" />
    <limit effort="66" lower="-3.1400001" upper="1.0470001" velocity="4.29" />
  </joint>
  <link name="left_shoulder_pitch_link">
    <inertial>
      <origin xyz="-0.00489 -0.0021666 -0.0000183" rpy="0 0 0" />
      <mass value="1.02367" />
      <inertia ixx="0.0009932" ixy="0.0000242" ixz="-0.0000073" iyy="0.0009029" iyz="-0.0000134" izz="0.0009814" />
    </inertial>
  </link>
  <joint name="left_shoulder_roll_joint" type="revolute">
    <origin xyz="-0.009 0 0" rpy="0 0 0" />
    <axis xyz="1 0 0" />
    <parent link="left_shoulder_pitch_link" />
    <child link="left_shoulder_roll_link" />
    <limit effort="66" lower="0" upper="2.3560002" velocity="4.29" />
  </joint>
  <link name="left_shoulder_roll_link">
    <inertial>
      <origin xyz="0.00046 0.0000202 -0.09827" rpy="0 0 0" />
      <mass value="1.19875" />
      <inertia ixx="0.0026264" ixy="0" ixz="0.0000126" iyy="0.0027416" iyz="0.0000066" izz="0.0013098" />
    </inertial>
    <collision name="Geom_53">
      <origin xyz="0 -0.0000206 -0.068" rpy="1.5707965 0.0003033 1.5707965" />
      <geometry>
        <box size="0.08 0.14 0.08" />
      </geometry>
    </collision>
  </link>
  <joint name="left_shoulder_yaw_joint" type="revolute">
    <origin xyz="0 -0.0000758 -0.25" rpy="0 0 0" />
    <axis xyz="0 0.0003032 1" />
    <parent link="left_shoulder_roll_link" />
    <child link="left_shoulder_yaw_link" />
    <limit effort="66" lower="-2.967" upper="2.967" velocity="4.29" />
  </joint>
  <link name="left_shoulder_yaw_link">
    <inertial>
      <origin xyz="-0.00499 -0.0147933 0.0550945" rpy="0 0 0" />
      <mass value="0.29744" />
      <inertia ixx="0.0006397" ixy="-0.0000053" ixz="0" iyy="0.0005912" iyz="0.0001552" izz="0.0003296" />
    </inertial>
    <collision name="Geom_55">
      <origin xyz="0 0.0000285 0.093834" rpy="0.0003032 0 -3.1415924" />
      <geometry>
        <box size="0.077792 0.077792 0.03" />
      </geometry>
    </collision>
    <collision name="Geom_56">
      <origin xyz="-0.016 0.0000197 0.064901" rpy="0.0003032 0 -3.1415924" />
      <geometry>
        <box size="0.045792 0.077792 0.033866" />
      </geometry>
    </collision>
  </link>
  <joint name="left_elbow_pitch_joint" type="revolute">
    <origin xyz="0 0 0" rpy="0 0 0" />
    <axis xyz="0 1 -0.0003032" />
    <parent link="left_shoulder_yaw_link" />
    <child link="left_elbow_pitch_link" />
    <limit effort="66" lower="-0.524" upper="1.5710001" velocity="4.29" />
  </joint>
  <link name="left_elbow_pitch_link">
    <inertial>
      <origin xyz="0.04407 0.00163 -0.0000605" rpy="0 0 0" />
      <mass value="1.59951" />
      <inertia ixx="0.0013106" ixy="-0.0001199" ixz="-0.0000038" iyy="0.0052826" iyz="0" izz="0.005226" />
    </inertial>
    <collision name="Geom_58">
      <origin xyz="0.096 0 0" rpy="-3.1408892 -1.5704931 1.5700932" />
      <geometry>
        <box size="0.082008 0.082008 0.082008" />
      </geometry>
    </collision>
  </link>
  <joint name="left_wrist_yaw_joint" type="revolute">
    <origin xyz="0.247 0 0" rpy="0 0 0" />
    <axis xyz="-1 0 0" />
    <parent link="left_elbow_pitch_link" />
    <child link="left_wrist_yaw_link" />
    <limit effort="34" lower="-2.967" upper="2.967" velocity="5.13" />
  </joint>
  <link name="left_wrist_yaw_link">
    <inertial>
      <origin xyz="-0.06275 0 -0.00151" rpy="0 0 0" />
      <mass value="0.63403" />
      <inertia ixx="0.0005753" ixy="0" ixz="-0.0000068" iyy="0.0009662" iyz="0" izz="0.0007936" />
    </inertial>
    <collision name="Geom_60">
      <origin xyz="-0.077271 0 0" rpy="-1.570796 0.0003033 1.5707967" />
      <geometry>
        <box size="0.082008 0.082008 0.051458" />
      </geometry>
    </collision>
  </link>
  <joint name="left_wrist_roll_joint" type="revolute">
    <origin xyz="0 0 0" rpy="0 0 0" />
    <axis xyz="0 0.0003033 1" />
    <parent link="left_wrist_yaw_link" />
    <child link="left_wrist_roll_link" />
    <limit effort="11" lower="-1.1339999" upper="0.698" velocity="6.17" />
  </joint>
  <link name="left_wrist_roll_link">
    <inertial>
      <origin xyz="0.00982 0.00219 0" rpy="0 0 0" />
      <mass value="0.4084" />
      <inertia ixx="0.0002487" ixy="0" ixz="0" iyy="0.0001904" iyz="0" izz="0.0002421" />
    </inertial>
    <collision name="Geom_62">
      <origin xyz="0.01 0 0" rpy="0.0003033 0 -3.1415922" />
      <geometry>
        <box size="0.058 0.064 0.058" />
      </geometry>
    </collision>
  </link>
  <joint name="left_wrist_pitch_joint" type="revolute">
    <origin xyz="0.01 0 0" rpy="0 0 0" />
    <axis xyz="0 1 -0.0003034" />
    <parent link="left_wrist_roll_link" />
    <child link="left_wrist_pitch_link" />
    <limit effort="11" lower="-0.96" upper="0.96" velocity="6.17" />
  </joint>
  <link name="left_wrist_pitch_link">
    <inertial>
      <origin xyz="0.03141 0.0184 0.0000044" rpy="0 0 0" />
      <mass value="0.14968" />
      <inertia ixx="0.0000851" ixy="-0.0000399" ixz="0" iyy="0.0000837" iyz="0" izz="0.0001146" />
    </inertial>
    <collision name="Geom_64">
      <origin xyz="0.04441 0.005139 0" rpy="1.5710997 0 -3.1415922" />
      <geometry>
        <box size="0.004798 0.066116 0.050442" />
      </geometry>
    </collision>
    <collision name="Geom_65">
      <origin xyz="0.01 0.038911 -0.0000118" rpy="1.5710997 0 -3.1415922" />
      <geometry>
        <box size="0.046798 0.044032 0.008442" />
      </geometry>
    </collision>
  </link>
  <joint name="right_shoulder_pitch_joint" type="revolute">
    <origin xyz="0 -0.2075 0.36753" rpy="0 0 0" />
    <axis xyz="0 0.9962185 -0.0868828" />
    <parent link="waist_roll_link" />
    <child link="right_shoulder_pitch_link" />
    <limit effort="66" lower="-3.1400001" upper="1.0470001" velocity="4.29" />
  </joint>
  <link name="right_shoulder_pitch_link">
    <inertial>
      <origin xyz="-0.00489 0.0021666 -0.0000183" rpy="0 0 0" />
      <mass value="1.02367" />
      <inertia ixx="0.0009932" ixy="-0.0000242" ixz="-0.0000073" iyy="0.0009029" iyz="0.0000134" izz="0.0009814" />
    </inertial>
  </link>
  <joint name="right_shoulder_roll_joint" type="revolute">
    <origin xyz="-0.009 0 0" rpy="0 0 0" />
    <axis xyz="1 0 0" />
    <parent link="right_shoulder_pitch_link" />
    <child link="right_shoulder_roll_link" />
    <limit effort="66" lower="-2.3560002" upper="0" velocity="4.29" />
  </joint>
  <link name="right_shoulder_roll_link">
    <inertial>
      <origin xyz="0.00046 -0.0000202 -0.09827" rpy="0 0 0" />
      <mass value="1.19875" />
      <inertia ixx="0.0026264" ixy="0" ixz="0.0000126" iyy="0.0027416" iyz="-0.0000066" izz="0.0013098" />
    </inertial>
    <collision name="Geom_68">
      <origin xyz="0 0.0000206 -0.068" rpy="1.5707964 -0.0003033 1.5707965" />
      <geometry>
        <box size="0.08 0.14 0.08" />
      </geometry>
    </collision>
  </link>
  <joint name="right_shoulder_yaw_joint" type="revolute">
    <origin xyz="0 0.0000758 -0.25" rpy="0 0 0" />
    <axis xyz="0 -0.0003033 1" />
    <parent link="right_shoulder_roll_link" />
    <child link="right_shoulder_yaw_link" />
    <limit effort="66" lower="-2.967" upper="2.967" velocity="4.29" />
  </joint>
  <link name="right_shoulder_yaw_link">
    <inertial>
      <origin xyz="-0.00499 -0.0148267 0.0550855" rpy="0 0 0" />
      <mass value="0.29744" />
      <inertia ixx="0.0006317" ixy="-0.0000059" ixz="0" iyy="0.0005871" iyz="0.0001515" izz="0.0003238" />
    </inertial>
    <collision name="Geom_70">
      <origin xyz="0 -0.0000285 0.093834" rpy="-0.0003033 0 -3.1415924" />
      <geometry>
        <box size="0.077792 0.077792 0.03" />
      </geometry>
    </collision>
    <collision name="Geom_71">
      <origin xyz="-0.016 -0.0000197 0.064901" rpy="-0.0003033 0 -3.1415924" />
      <geometry>
        <box size="0.045792 0.077792 0.033866" />
      </geometry>
    </collision>
  </link>
  <joint name="right_elbow_pitch_joint" type="revolute">
    <origin xyz="0 0 0" rpy="0 0 0" />
    <axis xyz="0 1 0.0003033" />
    <parent link="right_shoulder_yaw_link" />
    <child link="right_elbow_pitch_link" />
    <limit effort="66" lower="-0.524" upper="1.5710001" velocity="4.29" />
  </joint>
  <link name="right_elbow_pitch_link">
    <inertial>
      <origin xyz="0.04407 0.00163 -0.0000395" rpy="0 0 0" />
      <mass value="1.59951" />
      <inertia ixx="0.0013106" ixy="-0.0001203" ixz="0" iyy="0.0052826" iyz="0" izz="0.005226" />
    </inertial>
    <collision name="Geom_73">
      <origin xyz="0.096 0 0" rpy="-0.0004146 -1.570493 -1.5703814" />
      <geometry>
        <box size="0.082008 0.082008 0.082008" />
      </geometry>
    </collision>
  </link>
  <joint name="right_wrist_yaw_joint" type="revolute">
    <origin xyz="0.247 0 0" rpy="0 0 0" />
    <axis xyz="-1 0 0" />
    <parent link="right_elbow_pitch_link" />
    <child link="right_wrist_yaw_link" />
    <limit effort="34" lower="-2.967" upper="2.967" velocity="5.13" />
  </joint>
  <link name="right_wrist_yaw_link">
    <inertial>
      <origin xyz="-0.06275 0 0.00151" rpy="0 0 0" />
      <mass value="0.63403" />
      <inertia ixx="0.0005753" ixy="0" ixz="0.0000068" iyy="0.0009662" iyz="0" izz="0.0007936" />
    </inertial>
    <collision name="Geom_75">
      <origin xyz="-0.077271 0 0" rpy="-1.5707961 -0.0003033 1.5707967" />
      <geometry>
        <box size="0.082008 0.082008 0.051458" />
      </geometry>
    </collision>
  </link>
  <joint name="right_wrist_roll_joint" type="revolute">
    <origin xyz="0 0 0" rpy="0 0 0" />
    <axis xyz="0 -0.0003032 1" />
    <parent link="right_wrist_yaw_link" />
    <child link="right_wrist_roll_link" />
    <limit effort="11" lower="-0.698" upper="1.1339999" velocity="6.17" />
  </joint>
  <link name="right_wrist_roll_link">
    <inertial>
      <origin xyz="0.00982 -0.00219 0" rpy="0 0 0" />
      <mass value="0.4084" />
      <inertia ixx="0.0002487" ixy="0" ixz="0" iyy="0.0001904" iyz="0" izz="0.0002421" />
    </inertial>
    <collision name="Geom_77">
      <origin xyz="0.01 0 0" rpy="-0.0003032 0 -3.1415922" />
      <geometry>
        <box size="0.058 0.064 0.058" />
      </geometry>
    </collision>
  </link>
  <joint name="right_wrist_pitch_joint" type="revolute">
    <origin xyz="0.01 0 0" rpy="0 0 0" />
    <axis xyz="0 1 0.0003031" />
    <parent link="right_wrist_roll_link" />
    <child link="right_wrist_pitch_link" />
    <limit effort="11" lower="-0.96" upper="0.96" velocity="6.17" />
  </joint>
  <link name="right_wrist_pitch_link">
    <inertial>
      <origin xyz="0.03141 -0.0184 0.0000044" rpy="0 0 0" />
      <mass value="0.14968" />
      <inertia ixx="0.0000851" ixy="0.0000399" ixz="0" iyy="0.0000837" iyz="0" izz="0.0001146" />
    </inertial>
    <collision name="Geom_79">
      <origin xyz="0.04441 -0.005139 0" rpy="1.5704932 0 -3.1415922" />
      <geometry>
        <box size="0.004798 0.066116 0.050442" />
      </geometry>
    </collision>
    <collision name="Geom_80">
      <origin xyz="0.01 -0.038911 -0.0000118" rpy="1.5704932 0 -3.1415922" />
      <geometry>
        <box size="0.046798 0.044032 0.008442" />
      </geometry>
    </collision>
  </link>
  <joint name="head_yaw_joint" type="fixed">
    <origin xyz="-0.015 0 0.5881" rpy="0 0 0" />
    <parent link="waist_roll_link" />
    <child link="head_yaw_link" />
  </joint>
  <link name="head_yaw_link">
    <inertial>
      <origin xyz="-0.00099 0.00538 -0.0318" rpy="0 0 0" />
      <mass value="0.74204" />
      <inertia ixx="0.0018209" ixy="0" ixz="0.0000067" iyy="0.0017224" iyz="0.0001253" izz="0.0006037" />
    </inertial>
  </link>
  <joint name="head_pitch_joint" type="fixed">
    <origin xyz="0 0 0" rpy="0 0 0" />
    <parent link="head_yaw_link" />
    <child link="head_pitch_link" />
  </joint>
  <link name="head_pitch_link">
    <inertial>
      <origin xyz="0.03262 -0.0005 0.01482" rpy="0 0 0" />
      <mass value="0.88663" />
      <inertia ixx="0.0038077" ixy="0.0000053" ixz="-0.0003017" iyy="0.0052525" iyz="0.0000131" izz="0.0052373" />
    </inertial>
    <collision name="Geom_83">
      <origin xyz="0.025672 0 0.02359" rpy="1.5707964 0 -3.1415925" />
      <geometry>
        <box size="0.220186 0.155228 0.165464" />
      </geometry>
    </collision>
    <collision name="Geom_84">
      <origin xyz="0.08504 0 -0.07576" rpy="1.5707964 0 -3.1415925" />
      <geometry>
        <box size="0.082264 0.043472 0.12032" />
      </geometry>
    </collision>
  </link>
  <joint name="imu_joint" type="fixed">
    <origin xyz="-0.00614 0 -0.02485" rpy="0 0 0" />
    <parent link="pelvis" />
    <child link="imu_link" />
  </joint>
  <link name="imu_link" />
</robot>